Internal Server Error: /linchpin/employee/
Traceback (most recent call last):
  File "/usr/local/lib/python2.7/site-packages/django/core/handlers/base.py", line 98, in get_response
    resolver_match = resolver.resolve(request.path_info)
  File "/usr/local/lib/python2.7/site-packages/django/core/urlresolvers.py", line 343, in resolve
    for pattern in self.url_patterns:
  File "/usr/local/lib/python2.7/site-packages/django/core/urlresolvers.py", line 372, in url_patterns
    patterns = getattr(self.urlconf_module, "urlpatterns", self.urlconf_module)
  File "/usr/local/lib/python2.7/site-packages/django/core/urlresolvers.py", line 366, in urlconf_module
    self._urlconf_module = import_module(self.urlconf_name)
  File "/usr/local/Cellar/python/2.7.9/Frameworks/Python.framework/Versions/2.7/lib/python2.7/importlib/__init__.py", line 37, in import_module
    __import__(name)
  File "/Users/gaurav/GitRepo/cmpe295b/cmpe295b/urls.py", line 3, in <module>
    from linchpin.views import EmployeeView
  File "/Users/gaurav/GitRepo/cmpe295b/linchpin/views.py", line 50
    
    ^
IndentationError: unexpected unindent
Internal Server Error: /linchpin/teamInfo/
Traceback (most recent call last):
  File "/usr/local/lib/python2.7/site-packages/django/core/handlers/base.py", line 98, in get_response
    resolver_match = resolver.resolve(request.path_info)
  File "/usr/local/lib/python2.7/site-packages/django/core/urlresolvers.py", line 343, in resolve
    for pattern in self.url_patterns:
  File "/usr/local/lib/python2.7/site-packages/django/core/urlresolvers.py", line 372, in url_patterns
    patterns = getattr(self.urlconf_module, "urlpatterns", self.urlconf_module)
  File "/usr/local/lib/python2.7/site-packages/django/core/urlresolvers.py", line 366, in urlconf_module
    self._urlconf_module = import_module(self.urlconf_name)
  File "/usr/local/Cellar/python/2.7.9/Frameworks/Python.framework/Versions/2.7/lib/python2.7/importlib/__init__.py", line 37, in import_module
    __import__(name)
  File "/Users/gaurav/GitRepo/cmpe295b/cmpe295b/urls.py", line 3, in <module>
    from linchpin.views import EmployeeView
  File "/Users/gaurav/GitRepo/cmpe295b/linchpin/views.py", line 50
    
    ^
IndentationError: unexpected unindent
Internal Server Error: /linchpin/employee/
Traceback (most recent call last):
  File "/usr/local/lib/python2.7/site-packages/django/core/handlers/base.py", line 98, in get_response
    resolver_match = resolver.resolve(request.path_info)
  File "/usr/local/lib/python2.7/site-packages/django/core/urlresolvers.py", line 343, in resolve
    for pattern in self.url_patterns:
  File "/usr/local/lib/python2.7/site-packages/django/core/urlresolvers.py", line 372, in url_patterns
    patterns = getattr(self.urlconf_module, "urlpatterns", self.urlconf_module)
  File "/usr/local/lib/python2.7/site-packages/django/core/urlresolvers.py", line 366, in urlconf_module
    self._urlconf_module = import_module(self.urlconf_name)
  File "/usr/local/Cellar/python/2.7.9/Frameworks/Python.framework/Versions/2.7/lib/python2.7/importlib/__init__.py", line 37, in import_module
    __import__(name)
  File "/Users/gaurav/GitRepo/cmpe295b/cmpe295b/urls.py", line 3, in <module>
    from linchpin.views import EmployeeView
  File "/Users/gaurav/GitRepo/cmpe295b/linchpin/views.py", line 50
    
    ^
IndentationError: unexpected unindent
Internal Server Error: /linchpin/teamInfo/
Traceback (most recent call last):
  File "/usr/local/lib/python2.7/site-packages/django/core/handlers/base.py", line 98, in get_response
    resolver_match = resolver.resolve(request.path_info)
  File "/usr/local/lib/python2.7/site-packages/django/core/urlresolvers.py", line 343, in resolve
    for pattern in self.url_patterns:
  File "/usr/local/lib/python2.7/site-packages/django/core/urlresolvers.py", line 372, in url_patterns
    patterns = getattr(self.urlconf_module, "urlpatterns", self.urlconf_module)
  File "/usr/local/lib/python2.7/site-packages/django/core/urlresolvers.py", line 366, in urlconf_module
    self._urlconf_module = import_module(self.urlconf_name)
  File "/usr/local/Cellar/python/2.7.9/Frameworks/Python.framework/Versions/2.7/lib/python2.7/importlib/__init__.py", line 37, in import_module
    __import__(name)
  File "/Users/gaurav/GitRepo/cmpe295b/cmpe295b/urls.py", line 3, in <module>
    from linchpin.views import EmployeeView
  File "/Users/gaurav/GitRepo/cmpe295b/linchpin/views.py", line 50
    
    ^
IndentationError: unexpected unindent
Internal Server Error: /linchpin/employee/
Traceback (most recent call last):
  File "/usr/local/lib/python2.7/site-packages/django/core/handlers/base.py", line 98, in get_response
    resolver_match = resolver.resolve(request.path_info)
  File "/usr/local/lib/python2.7/site-packages/django/core/urlresolvers.py", line 343, in resolve
    for pattern in self.url_patterns:
  File "/usr/local/lib/python2.7/site-packages/django/core/urlresolvers.py", line 372, in url_patterns
    patterns = getattr(self.urlconf_module, "urlpatterns", self.urlconf_module)
  File "/usr/local/lib/python2.7/site-packages/django/core/urlresolvers.py", line 366, in urlconf_module
    self._urlconf_module = import_module(self.urlconf_name)
  File "/usr/local/Cellar/python/2.7.9/Frameworks/Python.framework/Versions/2.7/lib/python2.7/importlib/__init__.py", line 37, in import_module
    __import__(name)
  File "/Users/gaurav/GitRepo/cmpe295b/cmpe295b/urls.py", line 3, in <module>
    from linchpin.views import EmployeeView
  File "/Users/gaurav/GitRepo/cmpe295b/linchpin/views.py", line 50
    
    ^
IndentationError: unexpected unindent
Internal Server Error: /linchpin/employee/
Traceback (most recent call last):
  File "/usr/local/lib/python2.7/site-packages/django/core/handlers/base.py", line 98, in get_response
    resolver_match = resolver.resolve(request.path_info)
  File "/usr/local/lib/python2.7/site-packages/django/core/urlresolvers.py", line 343, in resolve
    for pattern in self.url_patterns:
  File "/usr/local/lib/python2.7/site-packages/django/core/urlresolvers.py", line 372, in url_patterns
    patterns = getattr(self.urlconf_module, "urlpatterns", self.urlconf_module)
  File "/usr/local/lib/python2.7/site-packages/django/core/urlresolvers.py", line 366, in urlconf_module
    self._urlconf_module = import_module(self.urlconf_name)
  File "/usr/local/Cellar/python/2.7.9/Frameworks/Python.framework/Versions/2.7/lib/python2.7/importlib/__init__.py", line 37, in import_module
    __import__(name)
  File "/Users/gaurav/GitRepo/cmpe295b/cmpe295b/urls.py", line 3, in <module>
    from linchpin.views import EmployeeView
  File "/Users/gaurav/GitRepo/cmpe295b/linchpin/views.py", line 50
    
    ^
IndentationError: unexpected unindent
Internal Server Error: /linchpin/employee/
Traceback (most recent call last):
  File "/usr/local/lib/python2.7/site-packages/django/core/handlers/base.py", line 98, in get_response
    resolver_match = resolver.resolve(request.path_info)
  File "/usr/local/lib/python2.7/site-packages/django/core/urlresolvers.py", line 343, in resolve
    for pattern in self.url_patterns:
  File "/usr/local/lib/python2.7/site-packages/django/core/urlresolvers.py", line 372, in url_patterns
    patterns = getattr(self.urlconf_module, "urlpatterns", self.urlconf_module)
  File "/usr/local/lib/python2.7/site-packages/django/core/urlresolvers.py", line 366, in urlconf_module
    self._urlconf_module = import_module(self.urlconf_name)
  File "/usr/local/Cellar/python/2.7.9/Frameworks/Python.framework/Versions/2.7/lib/python2.7/importlib/__init__.py", line 37, in import_module
    __import__(name)
  File "/Users/gaurav/GitRepo/cmpe295b/cmpe295b/urls.py", line 7, in <module>
    url(r'^linchpin/', include('linchpin.urls')),
  File "/usr/local/lib/python2.7/site-packages/django/conf/urls/__init__.py", line 28, in include
    urlconf_module = import_module(urlconf_module)
  File "/usr/local/Cellar/python/2.7.9/Frameworks/Python.framework/Versions/2.7/lib/python2.7/importlib/__init__.py", line 37, in import_module
    __import__(name)
  File "/Users/gaurav/GitRepo/cmpe295b/linchpin/urls.py", line 10
    url(r'^performance/$',TeamInfoView.as_view(), name='Performance')
      ^
SyntaxError: invalid syntax
Internal Server Error: /linchpin/employee/
Traceback (most recent call last):
  File "/usr/local/lib/python2.7/site-packages/django/core/handlers/base.py", line 98, in get_response
    resolver_match = resolver.resolve(request.path_info)
  File "/usr/local/lib/python2.7/site-packages/django/core/urlresolvers.py", line 343, in resolve
    for pattern in self.url_patterns:
  File "/usr/local/lib/python2.7/site-packages/django/core/urlresolvers.py", line 372, in url_patterns
    patterns = getattr(self.urlconf_module, "urlpatterns", self.urlconf_module)
  File "/usr/local/lib/python2.7/site-packages/django/core/urlresolvers.py", line 366, in urlconf_module
    self._urlconf_module = import_module(self.urlconf_name)
  File "/usr/local/Cellar/python/2.7.9/Frameworks/Python.framework/Versions/2.7/lib/python2.7/importlib/__init__.py", line 37, in import_module
    __import__(name)
  File "/Users/gaurav/GitRepo/cmpe295b/cmpe295b/urls.py", line 3, in <module>
    from linchpin.views import EmployeeView
  File "/Users/gaurav/GitRepo/cmpe295b/linchpin/views.py", line 49
    print "Team Id" teamId
                         ^
SyntaxError: invalid syntax
Internal Server Error: /linchpin/teamInfo/
Traceback (most recent call last):
  File "/usr/local/lib/python2.7/site-packages/django/core/handlers/base.py", line 111, in get_response
    response = wrapped_callback(request, *callback_args, **callback_kwargs)
  File "/usr/local/lib/python2.7/site-packages/django/views/decorators/csrf.py", line 57, in wrapped_view
    return view_func(*args, **kwargs)
  File "/usr/local/lib/python2.7/site-packages/django/views/generic/base.py", line 69, in view
    return self.dispatch(request, *args, **kwargs)
  File "/usr/local/lib/python2.7/site-packages/rest_framework/views.py", line 452, in dispatch
    response = self.handle_exception(exc)
  File "/usr/local/lib/python2.7/site-packages/rest_framework/views.py", line 449, in dispatch
    response = handler(request, *args, **kwargs)
  File "/Users/gaurav/GitRepo/cmpe295b/linchpin/views.py", line 50, in get
    result['teamInfo'] = Employee.objects.filter(team_Id=teamId).values('fname','lname');
  File "/usr/local/lib/python2.7/site-packages/django/db/models/manager.py", line 92, in manager_method
    return getattr(self.get_queryset(), name)(*args, **kwargs)
  File "/usr/local/lib/python2.7/site-packages/django/db/models/query.py", line 691, in filter
    return self._filter_or_exclude(False, *args, **kwargs)
  File "/usr/local/lib/python2.7/site-packages/django/db/models/query.py", line 709, in _filter_or_exclude
    clone.query.add_q(Q(*args, **kwargs))
  File "/usr/local/lib/python2.7/site-packages/django/db/models/sql/query.py", line 1331, in add_q
    clause, require_inner = self._add_q(where_part, self.used_aliases)
  File "/usr/local/lib/python2.7/site-packages/django/db/models/sql/query.py", line 1358, in _add_q
    current_negated=current_negated, connector=connector)
  File "/usr/local/lib/python2.7/site-packages/django/db/models/sql/query.py", line 1182, in build_filter
    lookups, parts, reffed_aggregate = self.solve_lookup_type(arg)
  File "/usr/local/lib/python2.7/site-packages/django/db/models/sql/query.py", line 1120, in solve_lookup_type
    _, field, _, lookup_parts = self.names_to_path(lookup_splitted, self.get_meta())
  File "/usr/local/lib/python2.7/site-packages/django/db/models/sql/query.py", line 1427, in names_to_path
    self.raise_field_error(opts, name)
  File "/usr/local/lib/python2.7/site-packages/django/db/models/sql/query.py", line 1433, in raise_field_error
    "Choices are: %s" % (name, ", ".join(available)))
FieldError: Cannot resolve keyword 'team_Id' into field. Choices are: emp_department, emp_designation, emp_id, fname, home_phone, id, lname, manager, team_id, work_email
Internal Server Error: /linchpin/employee/
Traceback (most recent call last):
  File "/usr/local/lib/python2.7/site-packages/django/core/handlers/base.py", line 98, in get_response
    resolver_match = resolver.resolve(request.path_info)
  File "/usr/local/lib/python2.7/site-packages/django/core/urlresolvers.py", line 343, in resolve
    for pattern in self.url_patterns:
  File "/usr/local/lib/python2.7/site-packages/django/core/urlresolvers.py", line 372, in url_patterns
    patterns = getattr(self.urlconf_module, "urlpatterns", self.urlconf_module)
  File "/usr/local/lib/python2.7/site-packages/django/core/urlresolvers.py", line 366, in urlconf_module
    self._urlconf_module = import_module(self.urlconf_name)
  File "/usr/local/Cellar/python/2.7.9/Frameworks/Python.framework/Versions/2.7/lib/python2.7/importlib/__init__.py", line 37, in import_module
    __import__(name)
  File "/Users/gaurav/GitRepo/cmpe295b/cmpe295b/urls.py", line 7, in <module>
    url(r'^linchpin/', include('linchpin.urls')),
  File "/usr/local/lib/python2.7/site-packages/django/conf/urls/__init__.py", line 28, in include
    urlconf_module = import_module(urlconf_module)
  File "/usr/local/Cellar/python/2.7.9/Frameworks/Python.framework/Versions/2.7/lib/python2.7/importlib/__init__.py", line 37, in import_module
    __import__(name)
  File "/Users/gaurav/GitRepo/cmpe295b/linchpin/urls.py", line 11
    url(r'^experience/$',JobHistoryView.as_view(), name='Experience')
      ^
SyntaxError: invalid syntax
Internal Server Error: /linchpin/experience/
Traceback (most recent call last):
  File "/usr/local/lib/python2.7/site-packages/django/core/handlers/base.py", line 98, in get_response
    resolver_match = resolver.resolve(request.path_info)
  File "/usr/local/lib/python2.7/site-packages/django/core/urlresolvers.py", line 343, in resolve
    for pattern in self.url_patterns:
  File "/usr/local/lib/python2.7/site-packages/django/core/urlresolvers.py", line 372, in url_patterns
    patterns = getattr(self.urlconf_module, "urlpatterns", self.urlconf_module)
  File "/usr/local/lib/python2.7/site-packages/django/core/urlresolvers.py", line 366, in urlconf_module
    self._urlconf_module = import_module(self.urlconf_name)
  File "/usr/local/Cellar/python/2.7.9/Frameworks/Python.framework/Versions/2.7/lib/python2.7/importlib/__init__.py", line 37, in import_module
    __import__(name)
  File "/Users/gaurav/GitRepo/cmpe295b/cmpe295b/urls.py", line 7, in <module>
    url(r'^linchpin/', include('linchpin.urls')),
  File "/usr/local/lib/python2.7/site-packages/django/conf/urls/__init__.py", line 28, in include
    urlconf_module = import_module(urlconf_module)
  File "/usr/local/Cellar/python/2.7.9/Frameworks/Python.framework/Versions/2.7/lib/python2.7/importlib/__init__.py", line 37, in import_module
    __import__(name)
  File "/Users/gaurav/GitRepo/cmpe295b/linchpin/urls.py", line 11
    url(r'^experience/$',JobHistoryView.as_view(), name='Experience')
      ^
SyntaxError: invalid syntax
Internal Server Error: /linchpin/employee/
Traceback (most recent call last):
  File "/usr/local/lib/python2.7/site-packages/django/core/handlers/base.py", line 98, in get_response
    resolver_match = resolver.resolve(request.path_info)
  File "/usr/local/lib/python2.7/site-packages/django/core/urlresolvers.py", line 343, in resolve
    for pattern in self.url_patterns:
  File "/usr/local/lib/python2.7/site-packages/django/core/urlresolvers.py", line 372, in url_patterns
    patterns = getattr(self.urlconf_module, "urlpatterns", self.urlconf_module)
  File "/usr/local/lib/python2.7/site-packages/django/core/urlresolvers.py", line 366, in urlconf_module
    self._urlconf_module = import_module(self.urlconf_name)
  File "/usr/local/Cellar/python/2.7.9/Frameworks/Python.framework/Versions/2.7/lib/python2.7/importlib/__init__.py", line 37, in import_module
    __import__(name)
  File "/Users/gaurav/GitRepo/cmpe295b/cmpe295b/urls.py", line 7, in <module>
    url(r'^linchpin/', include('linchpin.urls')),
  File "/usr/local/lib/python2.7/site-packages/django/conf/urls/__init__.py", line 28, in include
    urlconf_module = import_module(urlconf_module)
  File "/usr/local/Cellar/python/2.7.9/Frameworks/Python.framework/Versions/2.7/lib/python2.7/importlib/__init__.py", line 37, in import_module
    __import__(name)
  File "/Users/gaurav/GitRepo/cmpe295b/linchpin/urls.py", line 11
    url(r'^experience/$',JobHistoryView.as_view(), name='Experience')
      ^
SyntaxError: invalid syntax
Internal Server Error: /
Traceback (most recent call last):
  File "/usr/local/lib/python2.7/site-packages/django/core/handlers/base.py", line 98, in get_response
    resolver_match = resolver.resolve(request.path_info)
  File "/usr/local/lib/python2.7/site-packages/django/core/urlresolvers.py", line 343, in resolve
    for pattern in self.url_patterns:
  File "/usr/local/lib/python2.7/site-packages/django/core/urlresolvers.py", line 372, in url_patterns
    patterns = getattr(self.urlconf_module, "urlpatterns", self.urlconf_module)
  File "/usr/local/lib/python2.7/site-packages/django/core/urlresolvers.py", line 366, in urlconf_module
    self._urlconf_module = import_module(self.urlconf_name)
  File "/usr/local/Cellar/python/2.7.9/Frameworks/Python.framework/Versions/2.7/lib/python2.7/importlib/__init__.py", line 37, in import_module
    __import__(name)
  File "/Users/gaurav/GitRepo/cmpe295b/cmpe295b/urls.py", line 7, in <module>
    url(r'^linchpin/', include('linchpin.urls')),
  File "/usr/local/lib/python2.7/site-packages/django/conf/urls/__init__.py", line 28, in include
    urlconf_module = import_module(urlconf_module)
  File "/usr/local/Cellar/python/2.7.9/Frameworks/Python.framework/Versions/2.7/lib/python2.7/importlib/__init__.py", line 37, in import_module
    __import__(name)
  File "/Users/gaurav/GitRepo/cmpe295b/linchpin/urls.py", line 11
    url(r'^experience/$',JobHistoryView.as_view(), name='Experience')
      ^
SyntaxError: invalid syntax
Internal Server Error: /favicon.ico
Traceback (most recent call last):
  File "/usr/local/lib/python2.7/site-packages/django/core/handlers/base.py", line 87, in get_response
    response = middleware_method(request)
  File "/usr/local/lib/python2.7/site-packages/django/middleware/common.py", line 72, in process_request
    if (not urlresolvers.is_valid_path(request.path_info, urlconf) and
  File "/usr/local/lib/python2.7/site-packages/django/core/urlresolvers.py", line 619, in is_valid_path
    resolve(path, urlconf)
  File "/usr/local/lib/python2.7/site-packages/django/core/urlresolvers.py", line 494, in resolve
    return get_resolver(urlconf).resolve(path)
  File "/usr/local/lib/python2.7/site-packages/django/core/urlresolvers.py", line 343, in resolve
    for pattern in self.url_patterns:
  File "/usr/local/lib/python2.7/site-packages/django/core/urlresolvers.py", line 372, in url_patterns
    patterns = getattr(self.urlconf_module, "urlpatterns", self.urlconf_module)
  File "/usr/local/lib/python2.7/site-packages/django/core/urlresolvers.py", line 366, in urlconf_module
    self._urlconf_module = import_module(self.urlconf_name)
  File "/usr/local/Cellar/python/2.7.9/Frameworks/Python.framework/Versions/2.7/lib/python2.7/importlib/__init__.py", line 37, in import_module
    __import__(name)
  File "/Users/gaurav/GitRepo/cmpe295b/cmpe295b/urls.py", line 7, in <module>
    url(r'^linchpin/', include('linchpin.urls')),
  File "/usr/local/lib/python2.7/site-packages/django/conf/urls/__init__.py", line 28, in include
    urlconf_module = import_module(urlconf_module)
  File "/usr/local/Cellar/python/2.7.9/Frameworks/Python.framework/Versions/2.7/lib/python2.7/importlib/__init__.py", line 37, in import_module
    __import__(name)
  File "/Users/gaurav/GitRepo/cmpe295b/linchpin/urls.py", line 11
    url(r'^experience/$',JobHistoryView.as_view(), name='Experience')
      ^
SyntaxError: invalid syntax
Internal Server Error: /app
Traceback (most recent call last):
  File "/usr/local/lib/python2.7/site-packages/django/core/handlers/base.py", line 87, in get_response
    response = middleware_method(request)
  File "/usr/local/lib/python2.7/site-packages/django/middleware/common.py", line 72, in process_request
    if (not urlresolvers.is_valid_path(request.path_info, urlconf) and
  File "/usr/local/lib/python2.7/site-packages/django/core/urlresolvers.py", line 619, in is_valid_path
    resolve(path, urlconf)
  File "/usr/local/lib/python2.7/site-packages/django/core/urlresolvers.py", line 494, in resolve
    return get_resolver(urlconf).resolve(path)
  File "/usr/local/lib/python2.7/site-packages/django/core/urlresolvers.py", line 343, in resolve
    for pattern in self.url_patterns:
  File "/usr/local/lib/python2.7/site-packages/django/core/urlresolvers.py", line 372, in url_patterns
    patterns = getattr(self.urlconf_module, "urlpatterns", self.urlconf_module)
  File "/usr/local/lib/python2.7/site-packages/django/core/urlresolvers.py", line 366, in urlconf_module
    self._urlconf_module = import_module(self.urlconf_name)
  File "/usr/local/Cellar/python/2.7.9/Frameworks/Python.framework/Versions/2.7/lib/python2.7/importlib/__init__.py", line 37, in import_module
    __import__(name)
  File "/Users/gaurav/GitRepo/cmpe295b/cmpe295b/urls.py", line 7, in <module>
    url(r'^linchpin/', include('linchpin.urls')),
  File "/usr/local/lib/python2.7/site-packages/django/conf/urls/__init__.py", line 28, in include
    urlconf_module = import_module(urlconf_module)
  File "/usr/local/Cellar/python/2.7.9/Frameworks/Python.framework/Versions/2.7/lib/python2.7/importlib/__init__.py", line 37, in import_module
    __import__(name)
  File "/Users/gaurav/GitRepo/cmpe295b/linchpin/urls.py", line 11
    url(r'^experience/$',JobHistoryView.as_view(), name='Experience')
      ^
SyntaxError: invalid syntax
Internal Server Error: /favicon.ico
Traceback (most recent call last):
  File "/usr/local/lib/python2.7/site-packages/django/core/handlers/base.py", line 87, in get_response
    response = middleware_method(request)
  File "/usr/local/lib/python2.7/site-packages/django/middleware/common.py", line 72, in process_request
    if (not urlresolvers.is_valid_path(request.path_info, urlconf) and
  File "/usr/local/lib/python2.7/site-packages/django/core/urlresolvers.py", line 619, in is_valid_path
    resolve(path, urlconf)
  File "/usr/local/lib/python2.7/site-packages/django/core/urlresolvers.py", line 494, in resolve
    return get_resolver(urlconf).resolve(path)
  File "/usr/local/lib/python2.7/site-packages/django/core/urlresolvers.py", line 343, in resolve
    for pattern in self.url_patterns:
  File "/usr/local/lib/python2.7/site-packages/django/core/urlresolvers.py", line 372, in url_patterns
    patterns = getattr(self.urlconf_module, "urlpatterns", self.urlconf_module)
  File "/usr/local/lib/python2.7/site-packages/django/core/urlresolvers.py", line 366, in urlconf_module
    self._urlconf_module = import_module(self.urlconf_name)
  File "/usr/local/Cellar/python/2.7.9/Frameworks/Python.framework/Versions/2.7/lib/python2.7/importlib/__init__.py", line 37, in import_module
    __import__(name)
  File "/Users/gaurav/GitRepo/cmpe295b/cmpe295b/urls.py", line 7, in <module>
    url(r'^linchpin/', include('linchpin.urls')),
  File "/usr/local/lib/python2.7/site-packages/django/conf/urls/__init__.py", line 28, in include
    urlconf_module = import_module(urlconf_module)
  File "/usr/local/Cellar/python/2.7.9/Frameworks/Python.framework/Versions/2.7/lib/python2.7/importlib/__init__.py", line 37, in import_module
    __import__(name)
  File "/Users/gaurav/GitRepo/cmpe295b/linchpin/urls.py", line 11
    url(r'^experience/$',JobHistoryView.as_view(), name='Experience')
      ^
SyntaxError: invalid syntax
Internal Server Error: /linchpin
Traceback (most recent call last):
  File "/usr/local/lib/python2.7/site-packages/django/core/handlers/base.py", line 87, in get_response
    response = middleware_method(request)
  File "/usr/local/lib/python2.7/site-packages/django/middleware/common.py", line 72, in process_request
    if (not urlresolvers.is_valid_path(request.path_info, urlconf) and
  File "/usr/local/lib/python2.7/site-packages/django/core/urlresolvers.py", line 619, in is_valid_path
    resolve(path, urlconf)
  File "/usr/local/lib/python2.7/site-packages/django/core/urlresolvers.py", line 494, in resolve
    return get_resolver(urlconf).resolve(path)
  File "/usr/local/lib/python2.7/site-packages/django/core/urlresolvers.py", line 343, in resolve
    for pattern in self.url_patterns:
  File "/usr/local/lib/python2.7/site-packages/django/core/urlresolvers.py", line 372, in url_patterns
    patterns = getattr(self.urlconf_module, "urlpatterns", self.urlconf_module)
  File "/usr/local/lib/python2.7/site-packages/django/core/urlresolvers.py", line 366, in urlconf_module
    self._urlconf_module = import_module(self.urlconf_name)
  File "/usr/local/Cellar/python/2.7.9/Frameworks/Python.framework/Versions/2.7/lib/python2.7/importlib/__init__.py", line 37, in import_module
    __import__(name)
  File "/Users/gaurav/GitRepo/cmpe295b/cmpe295b/urls.py", line 7, in <module>
    url(r'^linchpin/', include('linchpin.urls')),
  File "/usr/local/lib/python2.7/site-packages/django/conf/urls/__init__.py", line 28, in include
    urlconf_module = import_module(urlconf_module)
  File "/usr/local/Cellar/python/2.7.9/Frameworks/Python.framework/Versions/2.7/lib/python2.7/importlib/__init__.py", line 37, in import_module
    __import__(name)
  File "/Users/gaurav/GitRepo/cmpe295b/linchpin/urls.py", line 11
    url(r'^experience/$',JobHistoryView.as_view(), name='Experience')
      ^
SyntaxError: invalid syntax
Internal Server Error: /favicon.ico
Traceback (most recent call last):
  File "/usr/local/lib/python2.7/site-packages/django/core/handlers/base.py", line 87, in get_response
    response = middleware_method(request)
  File "/usr/local/lib/python2.7/site-packages/django/middleware/common.py", line 72, in process_request
    if (not urlresolvers.is_valid_path(request.path_info, urlconf) and
  File "/usr/local/lib/python2.7/site-packages/django/core/urlresolvers.py", line 619, in is_valid_path
    resolve(path, urlconf)
  File "/usr/local/lib/python2.7/site-packages/django/core/urlresolvers.py", line 494, in resolve
    return get_resolver(urlconf).resolve(path)
  File "/usr/local/lib/python2.7/site-packages/django/core/urlresolvers.py", line 343, in resolve
    for pattern in self.url_patterns:
  File "/usr/local/lib/python2.7/site-packages/django/core/urlresolvers.py", line 372, in url_patterns
    patterns = getattr(self.urlconf_module, "urlpatterns", self.urlconf_module)
  File "/usr/local/lib/python2.7/site-packages/django/core/urlresolvers.py", line 366, in urlconf_module
    self._urlconf_module = import_module(self.urlconf_name)
  File "/usr/local/Cellar/python/2.7.9/Frameworks/Python.framework/Versions/2.7/lib/python2.7/importlib/__init__.py", line 37, in import_module
    __import__(name)
  File "/Users/gaurav/GitRepo/cmpe295b/cmpe295b/urls.py", line 7, in <module>
    url(r'^linchpin/', include('linchpin.urls')),
  File "/usr/local/lib/python2.7/site-packages/django/conf/urls/__init__.py", line 28, in include
    urlconf_module = import_module(urlconf_module)
  File "/usr/local/Cellar/python/2.7.9/Frameworks/Python.framework/Versions/2.7/lib/python2.7/importlib/__init__.py", line 37, in import_module
    __import__(name)
  File "/Users/gaurav/GitRepo/cmpe295b/linchpin/urls.py", line 11
    url(r'^experience/$',JobHistoryView.as_view(), name='Experience')
      ^
SyntaxError: invalid syntax
Internal Server Error: /
Traceback (most recent call last):
  File "/usr/local/lib/python2.7/site-packages/django/core/handlers/base.py", line 98, in get_response
    resolver_match = resolver.resolve(request.path_info)
  File "/usr/local/lib/python2.7/site-packages/django/core/urlresolvers.py", line 343, in resolve
    for pattern in self.url_patterns:
  File "/usr/local/lib/python2.7/site-packages/django/core/urlresolvers.py", line 372, in url_patterns
    patterns = getattr(self.urlconf_module, "urlpatterns", self.urlconf_module)
  File "/usr/local/lib/python2.7/site-packages/django/core/urlresolvers.py", line 366, in urlconf_module
    self._urlconf_module = import_module(self.urlconf_name)
  File "/usr/local/Cellar/python/2.7.9/Frameworks/Python.framework/Versions/2.7/lib/python2.7/importlib/__init__.py", line 37, in import_module
    __import__(name)
  File "/Users/gaurav/GitRepo/cmpe295b/cmpe295b/urls.py", line 7, in <module>
    url(r'^linchpin/', include('linchpin.urls')),
  File "/usr/local/lib/python2.7/site-packages/django/conf/urls/__init__.py", line 28, in include
    urlconf_module = import_module(urlconf_module)
  File "/usr/local/Cellar/python/2.7.9/Frameworks/Python.framework/Versions/2.7/lib/python2.7/importlib/__init__.py", line 37, in import_module
    __import__(name)
  File "/Users/gaurav/GitRepo/cmpe295b/linchpin/urls.py", line 11
    url(r'^experience/$',JobHistoryView.as_view(), name='Experience')
      ^
SyntaxError: invalid syntax
Internal Server Error: /favicon.ico
Traceback (most recent call last):
  File "/usr/local/lib/python2.7/site-packages/django/core/handlers/base.py", line 87, in get_response
    response = middleware_method(request)
  File "/usr/local/lib/python2.7/site-packages/django/middleware/common.py", line 72, in process_request
    if (not urlresolvers.is_valid_path(request.path_info, urlconf) and
  File "/usr/local/lib/python2.7/site-packages/django/core/urlresolvers.py", line 619, in is_valid_path
    resolve(path, urlconf)
  File "/usr/local/lib/python2.7/site-packages/django/core/urlresolvers.py", line 494, in resolve
    return get_resolver(urlconf).resolve(path)
  File "/usr/local/lib/python2.7/site-packages/django/core/urlresolvers.py", line 343, in resolve
    for pattern in self.url_patterns:
  File "/usr/local/lib/python2.7/site-packages/django/core/urlresolvers.py", line 372, in url_patterns
    patterns = getattr(self.urlconf_module, "urlpatterns", self.urlconf_module)
  File "/usr/local/lib/python2.7/site-packages/django/core/urlresolvers.py", line 366, in urlconf_module
    self._urlconf_module = import_module(self.urlconf_name)
  File "/usr/local/Cellar/python/2.7.9/Frameworks/Python.framework/Versions/2.7/lib/python2.7/importlib/__init__.py", line 37, in import_module
    __import__(name)
  File "/Users/gaurav/GitRepo/cmpe295b/cmpe295b/urls.py", line 7, in <module>
    url(r'^linchpin/', include('linchpin.urls')),
  File "/usr/local/lib/python2.7/site-packages/django/conf/urls/__init__.py", line 28, in include
    urlconf_module = import_module(urlconf_module)
  File "/usr/local/Cellar/python/2.7.9/Frameworks/Python.framework/Versions/2.7/lib/python2.7/importlib/__init__.py", line 37, in import_module
    __import__(name)
  File "/Users/gaurav/GitRepo/cmpe295b/linchpin/urls.py", line 11
    url(r'^experience/$',JobHistoryView.as_view(), name='Experience')
      ^
SyntaxError: invalid syntax
Internal Server Error: /
Traceback (most recent call last):
  File "/usr/local/lib/python2.7/site-packages/django/core/handlers/base.py", line 98, in get_response
    resolver_match = resolver.resolve(request.path_info)
  File "/usr/local/lib/python2.7/site-packages/django/core/urlresolvers.py", line 343, in resolve
    for pattern in self.url_patterns:
  File "/usr/local/lib/python2.7/site-packages/django/core/urlresolvers.py", line 372, in url_patterns
    patterns = getattr(self.urlconf_module, "urlpatterns", self.urlconf_module)
  File "/usr/local/lib/python2.7/site-packages/django/core/urlresolvers.py", line 366, in urlconf_module
    self._urlconf_module = import_module(self.urlconf_name)
  File "/usr/local/Cellar/python/2.7.9/Frameworks/Python.framework/Versions/2.7/lib/python2.7/importlib/__init__.py", line 37, in import_module
    __import__(name)
  File "/Users/gaurav/GitRepo/cmpe295b/cmpe295b/urls.py", line 7, in <module>
    url(r'^linchpin/', include('linchpin.urls')),
  File "/usr/local/lib/python2.7/site-packages/django/conf/urls/__init__.py", line 28, in include
    urlconf_module = import_module(urlconf_module)
  File "/usr/local/Cellar/python/2.7.9/Frameworks/Python.framework/Versions/2.7/lib/python2.7/importlib/__init__.py", line 37, in import_module
    __import__(name)
  File "/Users/gaurav/GitRepo/cmpe295b/linchpin/urls.py", line 11
    url(r'^experience/$',JobHistoryView.as_view(), name='Experience')
      ^
SyntaxError: invalid syntax
Internal Server Error: /favicon.ico
Traceback (most recent call last):
  File "/usr/local/lib/python2.7/site-packages/django/core/handlers/base.py", line 87, in get_response
    response = middleware_method(request)
  File "/usr/local/lib/python2.7/site-packages/django/middleware/common.py", line 72, in process_request
    if (not urlresolvers.is_valid_path(request.path_info, urlconf) and
  File "/usr/local/lib/python2.7/site-packages/django/core/urlresolvers.py", line 619, in is_valid_path
    resolve(path, urlconf)
  File "/usr/local/lib/python2.7/site-packages/django/core/urlresolvers.py", line 494, in resolve
    return get_resolver(urlconf).resolve(path)
  File "/usr/local/lib/python2.7/site-packages/django/core/urlresolvers.py", line 343, in resolve
    for pattern in self.url_patterns:
  File "/usr/local/lib/python2.7/site-packages/django/core/urlresolvers.py", line 372, in url_patterns
    patterns = getattr(self.urlconf_module, "urlpatterns", self.urlconf_module)
  File "/usr/local/lib/python2.7/site-packages/django/core/urlresolvers.py", line 366, in urlconf_module
    self._urlconf_module = import_module(self.urlconf_name)
  File "/usr/local/Cellar/python/2.7.9/Frameworks/Python.framework/Versions/2.7/lib/python2.7/importlib/__init__.py", line 37, in import_module
    __import__(name)
  File "/Users/gaurav/GitRepo/cmpe295b/cmpe295b/urls.py", line 7, in <module>
    url(r'^linchpin/', include('linchpin.urls')),
  File "/usr/local/lib/python2.7/site-packages/django/conf/urls/__init__.py", line 28, in include
    urlconf_module = import_module(urlconf_module)
  File "/usr/local/Cellar/python/2.7.9/Frameworks/Python.framework/Versions/2.7/lib/python2.7/importlib/__init__.py", line 37, in import_module
    __import__(name)
  File "/Users/gaurav/GitRepo/cmpe295b/linchpin/urls.py", line 11
    url(r'^experience/$',JobHistoryView.as_view(), name='Experience')
      ^
SyntaxError: invalid syntax
Internal Server Error: /
Traceback (most recent call last):
  File "/usr/local/lib/python2.7/site-packages/django/core/handlers/base.py", line 98, in get_response
    resolver_match = resolver.resolve(request.path_info)
  File "/usr/local/lib/python2.7/site-packages/django/core/urlresolvers.py", line 343, in resolve
    for pattern in self.url_patterns:
  File "/usr/local/lib/python2.7/site-packages/django/core/urlresolvers.py", line 372, in url_patterns
    patterns = getattr(self.urlconf_module, "urlpatterns", self.urlconf_module)
  File "/usr/local/lib/python2.7/site-packages/django/core/urlresolvers.py", line 366, in urlconf_module
    self._urlconf_module = import_module(self.urlconf_name)
  File "/usr/local/Cellar/python/2.7.9/Frameworks/Python.framework/Versions/2.7/lib/python2.7/importlib/__init__.py", line 37, in import_module
    __import__(name)
  File "/Users/gaurav/GitRepo/cmpe295b/cmpe295b/urls.py", line 7, in <module>
    url(r'^linchpin/', include('linchpin.urls')),
  File "/usr/local/lib/python2.7/site-packages/django/conf/urls/__init__.py", line 28, in include
    urlconf_module = import_module(urlconf_module)
  File "/usr/local/Cellar/python/2.7.9/Frameworks/Python.framework/Versions/2.7/lib/python2.7/importlib/__init__.py", line 37, in import_module
    __import__(name)
  File "/Users/gaurav/GitRepo/cmpe295b/linchpin/urls.py", line 10, in <module>
    url(r'^experience/$',JobHistoryView.as_view(), name='Experience')
NameError: name 'JobHistoryView' is not defined
Internal Server Error: /favicon.ico
Traceback (most recent call last):
  File "/usr/local/lib/python2.7/site-packages/django/core/handlers/base.py", line 87, in get_response
    response = middleware_method(request)
  File "/usr/local/lib/python2.7/site-packages/django/middleware/common.py", line 72, in process_request
    if (not urlresolvers.is_valid_path(request.path_info, urlconf) and
  File "/usr/local/lib/python2.7/site-packages/django/core/urlresolvers.py", line 619, in is_valid_path
    resolve(path, urlconf)
  File "/usr/local/lib/python2.7/site-packages/django/core/urlresolvers.py", line 494, in resolve
    return get_resolver(urlconf).resolve(path)
  File "/usr/local/lib/python2.7/site-packages/django/core/urlresolvers.py", line 343, in resolve
    for pattern in self.url_patterns:
  File "/usr/local/lib/python2.7/site-packages/django/core/urlresolvers.py", line 372, in url_patterns
    patterns = getattr(self.urlconf_module, "urlpatterns", self.urlconf_module)
  File "/usr/local/lib/python2.7/site-packages/django/core/urlresolvers.py", line 366, in urlconf_module
    self._urlconf_module = import_module(self.urlconf_name)
  File "/usr/local/Cellar/python/2.7.9/Frameworks/Python.framework/Versions/2.7/lib/python2.7/importlib/__init__.py", line 37, in import_module
    __import__(name)
  File "/Users/gaurav/GitRepo/cmpe295b/cmpe295b/urls.py", line 7, in <module>
    url(r'^linchpin/', include('linchpin.urls')),
  File "/usr/local/lib/python2.7/site-packages/django/conf/urls/__init__.py", line 28, in include
    urlconf_module = import_module(urlconf_module)
  File "/usr/local/Cellar/python/2.7.9/Frameworks/Python.framework/Versions/2.7/lib/python2.7/importlib/__init__.py", line 37, in import_module
    __import__(name)
  File "/Users/gaurav/GitRepo/cmpe295b/linchpin/urls.py", line 10, in <module>
    url(r'^experience/$',JobHistoryView.as_view(), name='Experience')
NameError: name 'JobHistoryView' is not defined
Internal Server Error: /linchpin/teamInfo/
Traceback (most recent call last):
  File "/usr/local/lib/python2.7/site-packages/django/core/handlers/base.py", line 111, in get_response
    response = wrapped_callback(request, *callback_args, **callback_kwargs)
  File "/usr/local/lib/python2.7/site-packages/django/views/decorators/csrf.py", line 57, in wrapped_view
    return view_func(*args, **kwargs)
  File "/usr/local/lib/python2.7/site-packages/django/views/generic/base.py", line 69, in view
    return self.dispatch(request, *args, **kwargs)
  File "/usr/local/lib/python2.7/site-packages/rest_framework/views.py", line 452, in dispatch
    response = self.handle_exception(exc)
  File "/usr/local/lib/python2.7/site-packages/rest_framework/views.py", line 449, in dispatch
    response = handler(request, *args, **kwargs)
  File "/Users/gaurav/GitRepo/cmpe295b/linchpin/views.py", line 50, in get
    result['teamInfo'] = Employee.objects.filter(team_id=teamId).values('fname','lname','fbusername')
  File "/usr/local/lib/python2.7/site-packages/django/db/models/query.py", line 626, in values
    return self._clone(klass=ValuesQuerySet, setup=True, _fields=fields)
  File "/usr/local/lib/python2.7/site-packages/django/db/models/query.py", line 961, in _clone
    c._setup_query()
  File "/usr/local/lib/python2.7/site-packages/django/db/models/query.py", line 1129, in _setup_query
    self.query.add_fields(self.field_names, True)
  File "/usr/local/lib/python2.7/site-packages/django/db/models/sql/query.py", line 1670, in add_fields
    "Choices are: %s" % (name, ", ".join(names)))
FieldError: Cannot resolve keyword 'fbusername' into field. Choices are: emp_department, emp_designation, emp_id, fname, home_phone, id, joiningDate, lname, manager, team_id, totalExprience, work_email
Internal Server Error: /linchpin/teamInfo/
Traceback (most recent call last):
  File "/usr/local/lib/python2.7/site-packages/django/core/handlers/base.py", line 111, in get_response
    response = wrapped_callback(request, *callback_args, **callback_kwargs)
  File "/usr/local/lib/python2.7/site-packages/django/views/decorators/csrf.py", line 57, in wrapped_view
    return view_func(*args, **kwargs)
  File "/usr/local/lib/python2.7/site-packages/django/views/generic/base.py", line 69, in view
    return self.dispatch(request, *args, **kwargs)
  File "/usr/local/lib/python2.7/site-packages/rest_framework/views.py", line 452, in dispatch
    response = self.handle_exception(exc)
  File "/usr/local/lib/python2.7/site-packages/rest_framework/views.py", line 449, in dispatch
    response = handler(request, *args, **kwargs)
  File "/Users/gaurav/GitRepo/cmpe295b/linchpin/views.py", line 50, in get
    result['teamInfo'] = Employee.objects.filter(team_id=teamId).values('fname','lname','fbusername')
  File "/usr/local/lib/python2.7/site-packages/django/db/models/query.py", line 626, in values
    return self._clone(klass=ValuesQuerySet, setup=True, _fields=fields)
  File "/usr/local/lib/python2.7/site-packages/django/db/models/query.py", line 961, in _clone
    c._setup_query()
  File "/usr/local/lib/python2.7/site-packages/django/db/models/query.py", line 1129, in _setup_query
    self.query.add_fields(self.field_names, True)
  File "/usr/local/lib/python2.7/site-packages/django/db/models/sql/query.py", line 1670, in add_fields
    "Choices are: %s" % (name, ", ".join(names)))
FieldError: Cannot resolve keyword 'fbusername' into field. Choices are: emp_department, emp_designation, emp_id, fname, home_phone, id, joiningDate, lname, manager, team_id, totalExprience, work_email
Internal Server Error: /linchpin/employee/
Traceback (most recent call last):
  File "/usr/local/lib/python2.7/site-packages/django/core/handlers/base.py", line 98, in get_response
    resolver_match = resolver.resolve(request.path_info)
  File "/usr/local/lib/python2.7/site-packages/django/core/urlresolvers.py", line 343, in resolve
    for pattern in self.url_patterns:
  File "/usr/local/lib/python2.7/site-packages/django/core/urlresolvers.py", line 372, in url_patterns
    patterns = getattr(self.urlconf_module, "urlpatterns", self.urlconf_module)
  File "/usr/local/lib/python2.7/site-packages/django/core/urlresolvers.py", line 366, in urlconf_module
    self._urlconf_module = import_module(self.urlconf_name)
  File "/usr/local/Cellar/python/2.7.9/Frameworks/Python.framework/Versions/2.7/lib/python2.7/importlib/__init__.py", line 37, in import_module
    __import__(name)
  File "/Users/gaurav/GitRepo/cmpe295b/cmpe295b/urls.py", line 3, in <module>
    from linchpin.views import EmployeeView
  File "/Users/gaurav/GitRepo/cmpe295b/linchpin/views.py", line 64
    print result
                   ^
IndentationError: unindent does not match any outer indentation level
Internal Server Error: /linchpin/experience/
Traceback (most recent call last):
  File "/usr/local/lib/python2.7/site-packages/django/core/handlers/base.py", line 98, in get_response
    resolver_match = resolver.resolve(request.path_info)
  File "/usr/local/lib/python2.7/site-packages/django/core/urlresolvers.py", line 343, in resolve
    for pattern in self.url_patterns:
  File "/usr/local/lib/python2.7/site-packages/django/core/urlresolvers.py", line 372, in url_patterns
    patterns = getattr(self.urlconf_module, "urlpatterns", self.urlconf_module)
  File "/usr/local/lib/python2.7/site-packages/django/core/urlresolvers.py", line 366, in urlconf_module
    self._urlconf_module = import_module(self.urlconf_name)
  File "/usr/local/Cellar/python/2.7.9/Frameworks/Python.framework/Versions/2.7/lib/python2.7/importlib/__init__.py", line 37, in import_module
    __import__(name)
  File "/Users/gaurav/GitRepo/cmpe295b/cmpe295b/urls.py", line 3, in <module>
    from linchpin.views import EmployeeView
  File "/Users/gaurav/GitRepo/cmpe295b/linchpin/views.py", line 64
    print result
                   ^
IndentationError: unindent does not match any outer indentation level
Internal Server Error: /linchpin/employee/
Traceback (most recent call last):
  File "/usr/local/lib/python2.7/site-packages/django/core/handlers/base.py", line 98, in get_response
    resolver_match = resolver.resolve(request.path_info)
  File "/usr/local/lib/python2.7/site-packages/django/core/urlresolvers.py", line 343, in resolve
    for pattern in self.url_patterns:
  File "/usr/local/lib/python2.7/site-packages/django/core/urlresolvers.py", line 372, in url_patterns
    patterns = getattr(self.urlconf_module, "urlpatterns", self.urlconf_module)
  File "/usr/local/lib/python2.7/site-packages/django/core/urlresolvers.py", line 366, in urlconf_module
    self._urlconf_module = import_module(self.urlconf_name)
  File "/usr/local/Cellar/python/2.7.9/Frameworks/Python.framework/Versions/2.7/lib/python2.7/importlib/__init__.py", line 37, in import_module
    __import__(name)
  File "/Users/gaurav/GitRepo/cmpe295b/cmpe295b/urls.py", line 3, in <module>
    from linchpin.views import EmployeeView
  File "/Users/gaurav/GitRepo/cmpe295b/linchpin/views.py", line 64
    print result
                   ^
IndentationError: unindent does not match any outer indentation level
Internal Server Error: /linchpin/experience/
Traceback (most recent call last):
  File "/usr/local/lib/python2.7/site-packages/django/core/handlers/base.py", line 98, in get_response
    resolver_match = resolver.resolve(request.path_info)
  File "/usr/local/lib/python2.7/site-packages/django/core/urlresolvers.py", line 343, in resolve
    for pattern in self.url_patterns:
  File "/usr/local/lib/python2.7/site-packages/django/core/urlresolvers.py", line 372, in url_patterns
    patterns = getattr(self.urlconf_module, "urlpatterns", self.urlconf_module)
  File "/usr/local/lib/python2.7/site-packages/django/core/urlresolvers.py", line 366, in urlconf_module
    self._urlconf_module = import_module(self.urlconf_name)
  File "/usr/local/Cellar/python/2.7.9/Frameworks/Python.framework/Versions/2.7/lib/python2.7/importlib/__init__.py", line 37, in import_module
    __import__(name)
  File "/Users/gaurav/GitRepo/cmpe295b/cmpe295b/urls.py", line 3, in <module>
    from linchpin.views import EmployeeView
  File "/Users/gaurav/GitRepo/cmpe295b/linchpin/views.py", line 64
    print result
                   ^
IndentationError: unindent does not match any outer indentation level
Internal Server Error: /linchpin/employee/
Traceback (most recent call last):
  File "/usr/local/lib/python2.7/site-packages/django/core/handlers/base.py", line 98, in get_response
    resolver_match = resolver.resolve(request.path_info)
  File "/usr/local/lib/python2.7/site-packages/django/core/urlresolvers.py", line 343, in resolve
    for pattern in self.url_patterns:
  File "/usr/local/lib/python2.7/site-packages/django/core/urlresolvers.py", line 372, in url_patterns
    patterns = getattr(self.urlconf_module, "urlpatterns", self.urlconf_module)
  File "/usr/local/lib/python2.7/site-packages/django/core/urlresolvers.py", line 366, in urlconf_module
    self._urlconf_module = import_module(self.urlconf_name)
  File "/usr/local/Cellar/python/2.7.9/Frameworks/Python.framework/Versions/2.7/lib/python2.7/importlib/__init__.py", line 37, in import_module
    __import__(name)
  File "/Users/gaurav/GitRepo/cmpe295b/cmpe295b/urls.py", line 3, in <module>
    from linchpin.views import EmployeeView
  File "/Users/gaurav/GitRepo/cmpe295b/linchpin/views.py", line 64
    print result
               ^
IndentationError: unindent does not match any outer indentation level
Internal Server Error: /linchpin/experience/
Traceback (most recent call last):
  File "/usr/local/lib/python2.7/site-packages/django/core/handlers/base.py", line 98, in get_response
    resolver_match = resolver.resolve(request.path_info)
  File "/usr/local/lib/python2.7/site-packages/django/core/urlresolvers.py", line 343, in resolve
    for pattern in self.url_patterns:
  File "/usr/local/lib/python2.7/site-packages/django/core/urlresolvers.py", line 372, in url_patterns
    patterns = getattr(self.urlconf_module, "urlpatterns", self.urlconf_module)
  File "/usr/local/lib/python2.7/site-packages/django/core/urlresolvers.py", line 366, in urlconf_module
    self._urlconf_module = import_module(self.urlconf_name)
  File "/usr/local/Cellar/python/2.7.9/Frameworks/Python.framework/Versions/2.7/lib/python2.7/importlib/__init__.py", line 37, in import_module
    __import__(name)
  File "/Users/gaurav/GitRepo/cmpe295b/cmpe295b/urls.py", line 3, in <module>
    from linchpin.views import EmployeeView
  File "/Users/gaurav/GitRepo/cmpe295b/linchpin/views.py", line 64
    print result
               ^
IndentationError: unindent does not match any outer indentation level
Internal Server Error: /linchpin/employee/
Traceback (most recent call last):
  File "/usr/local/lib/python2.7/site-packages/django/core/handlers/base.py", line 98, in get_response
    resolver_match = resolver.resolve(request.path_info)
  File "/usr/local/lib/python2.7/site-packages/django/core/urlresolvers.py", line 343, in resolve
    for pattern in self.url_patterns:
  File "/usr/local/lib/python2.7/site-packages/django/core/urlresolvers.py", line 372, in url_patterns
    patterns = getattr(self.urlconf_module, "urlpatterns", self.urlconf_module)
  File "/usr/local/lib/python2.7/site-packages/django/core/urlresolvers.py", line 366, in urlconf_module
    self._urlconf_module = import_module(self.urlconf_name)
  File "/usr/local/Cellar/python/2.7.9/Frameworks/Python.framework/Versions/2.7/lib/python2.7/importlib/__init__.py", line 37, in import_module
    __import__(name)
  File "/Users/gaurav/GitRepo/cmpe295b/cmpe295b/urls.py", line 3, in <module>
    from linchpin.views import EmployeeView
  File "/Users/gaurav/GitRepo/cmpe295b/linchpin/views.py", line 64
    except:
    ^
IndentationError: unexpected unindent
Internal Server Error: /linchpin/employee/
Traceback (most recent call last):
  File "/usr/local/lib/python2.7/site-packages/django/core/handlers/base.py", line 98, in get_response
    resolver_match = resolver.resolve(request.path_info)
  File "/usr/local/lib/python2.7/site-packages/django/core/urlresolvers.py", line 343, in resolve
    for pattern in self.url_patterns:
  File "/usr/local/lib/python2.7/site-packages/django/core/urlresolvers.py", line 372, in url_patterns
    patterns = getattr(self.urlconf_module, "urlpatterns", self.urlconf_module)
  File "/usr/local/lib/python2.7/site-packages/django/core/urlresolvers.py", line 366, in urlconf_module
    self._urlconf_module = import_module(self.urlconf_name)
  File "/usr/local/Cellar/python/2.7.9/Frameworks/Python.framework/Versions/2.7/lib/python2.7/importlib/__init__.py", line 37, in import_module
    __import__(name)
  File "/Users/gaurav/GitRepo/cmpe295b/cmpe295b/urls.py", line 3, in <module>
    from linchpin.views import EmployeeView
  File "/Users/gaurav/GitRepo/cmpe295b/linchpin/views.py", line 60
    try:
      ^
IndentationError: expected an indented block
Internal Server Error: /linchpin/compensation/
Traceback (most recent call last):
  File "/usr/local/lib/python2.7/site-packages/django/core/handlers/base.py", line 98, in get_response
    resolver_match = resolver.resolve(request.path_info)
  File "/usr/local/lib/python2.7/site-packages/django/core/urlresolvers.py", line 343, in resolve
    for pattern in self.url_patterns:
  File "/usr/local/lib/python2.7/site-packages/django/core/urlresolvers.py", line 372, in url_patterns
    patterns = getattr(self.urlconf_module, "urlpatterns", self.urlconf_module)
  File "/usr/local/lib/python2.7/site-packages/django/core/urlresolvers.py", line 366, in urlconf_module
    self._urlconf_module = import_module(self.urlconf_name)
  File "/usr/local/Cellar/python/2.7.9/Frameworks/Python.framework/Versions/2.7/lib/python2.7/importlib/__init__.py", line 37, in import_module
    __import__(name)
  File "/Users/gaurav/GitRepo/cmpe295b/cmpe295b/urls.py", line 3, in <module>
    from linchpin.views import EmployeeView
  File "/Users/gaurav/GitRepo/cmpe295b/linchpin/views.py", line 60
    try:
      ^
IndentationError: expected an indented block
Internal Server Error: /linchpin/employee/
Traceback (most recent call last):
  File "/usr/local/lib/python2.7/site-packages/django/core/handlers/base.py", line 98, in get_response
    resolver_match = resolver.resolve(request.path_info)
  File "/usr/local/lib/python2.7/site-packages/django/core/urlresolvers.py", line 343, in resolve
    for pattern in self.url_patterns:
  File "/usr/local/lib/python2.7/site-packages/django/core/urlresolvers.py", line 372, in url_patterns
    patterns = getattr(self.urlconf_module, "urlpatterns", self.urlconf_module)
  File "/usr/local/lib/python2.7/site-packages/django/core/urlresolvers.py", line 366, in urlconf_module
    self._urlconf_module = import_module(self.urlconf_name)
  File "/usr/local/Cellar/python/2.7.9/Frameworks/Python.framework/Versions/2.7/lib/python2.7/importlib/__init__.py", line 37, in import_module
    __import__(name)
  File "/Users/gaurav/GitRepo/cmpe295b/cmpe295b/urls.py", line 3, in <module>
    from linchpin.views import EmployeeView
  File "/Users/gaurav/GitRepo/cmpe295b/linchpin/views.py", line 60
    try:
      ^
IndentationError: expected an indented block
Internal Server Error: /linchpin/experience/
Traceback (most recent call last):
  File "/usr/local/lib/python2.7/site-packages/django/core/handlers/base.py", line 98, in get_response
    resolver_match = resolver.resolve(request.path_info)
  File "/usr/local/lib/python2.7/site-packages/django/core/urlresolvers.py", line 343, in resolve
    for pattern in self.url_patterns:
  File "/usr/local/lib/python2.7/site-packages/django/core/urlresolvers.py", line 372, in url_patterns
    patterns = getattr(self.urlconf_module, "urlpatterns", self.urlconf_module)
  File "/usr/local/lib/python2.7/site-packages/django/core/urlresolvers.py", line 366, in urlconf_module
    self._urlconf_module = import_module(self.urlconf_name)
  File "/usr/local/Cellar/python/2.7.9/Frameworks/Python.framework/Versions/2.7/lib/python2.7/importlib/__init__.py", line 37, in import_module
    __import__(name)
  File "/Users/gaurav/GitRepo/cmpe295b/cmpe295b/urls.py", line 3, in <module>
    from linchpin.views import EmployeeView
  File "/Users/gaurav/GitRepo/cmpe295b/linchpin/views.py", line 60
    try:
      ^
IndentationError: expected an indented block
Internal Server Error: /linchpin/employee/
Traceback (most recent call last):
  File "/usr/local/lib/python2.7/site-packages/django/core/handlers/base.py", line 98, in get_response
    resolver_match = resolver.resolve(request.path_info)
  File "/usr/local/lib/python2.7/site-packages/django/core/urlresolvers.py", line 343, in resolve
    for pattern in self.url_patterns:
  File "/usr/local/lib/python2.7/site-packages/django/core/urlresolvers.py", line 372, in url_patterns
    patterns = getattr(self.urlconf_module, "urlpatterns", self.urlconf_module)
  File "/usr/local/lib/python2.7/site-packages/django/core/urlresolvers.py", line 366, in urlconf_module
    self._urlconf_module = import_module(self.urlconf_name)
  File "/usr/local/Cellar/python/2.7.9/Frameworks/Python.framework/Versions/2.7/lib/python2.7/importlib/__init__.py", line 37, in import_module
    __import__(name)
  File "/Users/gaurav/GitRepo/cmpe295b/cmpe295b/urls.py", line 3, in <module>
    from linchpin.views import EmployeeView
  File "/Users/gaurav/GitRepo/cmpe295b/linchpin/views.py", line 60
    try:
      ^
IndentationError: expected an indented block
Internal Server Error: /linchpin/teamInfo/
Traceback (most recent call last):
  File "/usr/local/lib/python2.7/site-packages/django/core/handlers/base.py", line 98, in get_response
    resolver_match = resolver.resolve(request.path_info)
  File "/usr/local/lib/python2.7/site-packages/django/core/urlresolvers.py", line 343, in resolve
    for pattern in self.url_patterns:
  File "/usr/local/lib/python2.7/site-packages/django/core/urlresolvers.py", line 372, in url_patterns
    patterns = getattr(self.urlconf_module, "urlpatterns", self.urlconf_module)
  File "/usr/local/lib/python2.7/site-packages/django/core/urlresolvers.py", line 366, in urlconf_module
    self._urlconf_module = import_module(self.urlconf_name)
  File "/usr/local/Cellar/python/2.7.9/Frameworks/Python.framework/Versions/2.7/lib/python2.7/importlib/__init__.py", line 37, in import_module
    __import__(name)
  File "/Users/gaurav/GitRepo/cmpe295b/cmpe295b/urls.py", line 3, in <module>
    from linchpin.views import EmployeeView
  File "/Users/gaurav/GitRepo/cmpe295b/linchpin/views.py", line 60
    try:
      ^
IndentationError: expected an indented block
Internal Server Error: /linchpin/employee/
Traceback (most recent call last):
  File "/usr/local/lib/python2.7/site-packages/django/core/handlers/base.py", line 98, in get_response
    resolver_match = resolver.resolve(request.path_info)
  File "/usr/local/lib/python2.7/site-packages/django/core/urlresolvers.py", line 343, in resolve
    for pattern in self.url_patterns:
  File "/usr/local/lib/python2.7/site-packages/django/core/urlresolvers.py", line 372, in url_patterns
    patterns = getattr(self.urlconf_module, "urlpatterns", self.urlconf_module)
  File "/usr/local/lib/python2.7/site-packages/django/core/urlresolvers.py", line 366, in urlconf_module
    self._urlconf_module = import_module(self.urlconf_name)
  File "/usr/local/Cellar/python/2.7.9/Frameworks/Python.framework/Versions/2.7/lib/python2.7/importlib/__init__.py", line 37, in import_module
    __import__(name)
  File "/Users/gaurav/GitRepo/cmpe295b/cmpe295b/urls.py", line 7, in <module>
    url(r'^linchpin/', include('linchpin.urls')),
  File "/usr/local/lib/python2.7/site-packages/django/conf/urls/__init__.py", line 28, in include
    urlconf_module = import_module(urlconf_module)
  File "/usr/local/Cellar/python/2.7.9/Frameworks/Python.framework/Versions/2.7/lib/python2.7/importlib/__init__.py", line 37, in import_module
    __import__(name)
  File "/Users/gaurav/GitRepo/cmpe295b/linchpin/urls.py", line 11
    url(r'^directory/$', DirectoryView.as_view(), name='Directory')
      ^
SyntaxError: invalid syntax
Internal Server Error: /linchpin/directory/
Traceback (most recent call last):
  File "/usr/local/lib/python2.7/site-packages/django/core/handlers/base.py", line 137, in get_response
    response = response.render()
  File "/usr/local/lib/python2.7/site-packages/django/template/response.py", line 103, in render
    self.content = self.rendered_content
  File "/usr/local/lib/python2.7/site-packages/rest_framework/response.py", line 59, in rendered_content
    ret = renderer.render(self.data, media_type, context)
  File "/usr/local/lib/python2.7/site-packages/rest_framework/renderers.py", line 99, in render
    separators=separators
  File "/usr/local/Cellar/python/2.7.9/Frameworks/Python.framework/Versions/2.7/lib/python2.7/json/__init__.py", line 250, in dumps
    sort_keys=sort_keys, **kw).encode(obj)
  File "/usr/local/Cellar/python/2.7.9/Frameworks/Python.framework/Versions/2.7/lib/python2.7/json/encoder.py", line 207, in encode
    chunks = self.iterencode(o, _one_shot=True)
  File "/usr/local/Cellar/python/2.7.9/Frameworks/Python.framework/Versions/2.7/lib/python2.7/json/encoder.py", line 270, in iterencode
    return _iterencode(o, 0)
  File "/usr/local/lib/python2.7/site-packages/rest_framework/utils/encoders.py", line 61, in default
    return super(JSONEncoder, self).default(obj)
  File "/usr/local/Cellar/python/2.7.9/Frameworks/Python.framework/Versions/2.7/lib/python2.7/json/encoder.py", line 184, in default
    raise TypeError(repr(o) + " is not JSON serializable")
TypeError: <Employee: Employee object> is not JSON serializable
Internal Server Error: /linchpin/employee/
Traceback (most recent call last):
  File "/usr/local/lib/python2.7/site-packages/django/core/handlers/base.py", line 98, in get_response
    resolver_match = resolver.resolve(request.path_info)
  File "/usr/local/lib/python2.7/site-packages/django/core/urlresolvers.py", line 343, in resolve
    for pattern in self.url_patterns:
  File "/usr/local/lib/python2.7/site-packages/django/core/urlresolvers.py", line 372, in url_patterns
    patterns = getattr(self.urlconf_module, "urlpatterns", self.urlconf_module)
  File "/usr/local/lib/python2.7/site-packages/django/core/urlresolvers.py", line 366, in urlconf_module
    self._urlconf_module = import_module(self.urlconf_name)
  File "/usr/local/Cellar/python/2.7.9/Frameworks/Python.framework/Versions/2.7/lib/python2.7/importlib/__init__.py", line 37, in import_module
    __import__(name)
  File "/Users/gaurav/GitRepo/cmpe295b/cmpe295b/urls.py", line 7, in <module>
    url(r'^linchpin/', include('linchpin.urls')),
  File "/usr/local/lib/python2.7/site-packages/django/conf/urls/__init__.py", line 28, in include
    urlconf_module = import_module(urlconf_module)
  File "/usr/local/Cellar/python/2.7.9/Frameworks/Python.framework/Versions/2.7/lib/python2.7/importlib/__init__.py", line 37, in import_module
    __import__(name)
  File "/Users/gaurav/GitRepo/cmpe295b/linchpin/urls.py", line 12, in <module>
    url(r'^adsearch/$', AdvancedSearchDirectoryView.as_view(), name='SearchDirectory')
NameError: name 'AdvancedSearchDirectoryView' is not defined
Internal Server Error: /linchpin/directory/
Traceback (most recent call last):
  File "/usr/local/lib/python2.7/site-packages/django/core/handlers/base.py", line 98, in get_response
    resolver_match = resolver.resolve(request.path_info)
  File "/usr/local/lib/python2.7/site-packages/django/core/urlresolvers.py", line 343, in resolve
    for pattern in self.url_patterns:
  File "/usr/local/lib/python2.7/site-packages/django/core/urlresolvers.py", line 372, in url_patterns
    patterns = getattr(self.urlconf_module, "urlpatterns", self.urlconf_module)
  File "/usr/local/lib/python2.7/site-packages/django/core/urlresolvers.py", line 366, in urlconf_module
    self._urlconf_module = import_module(self.urlconf_name)
  File "/usr/local/Cellar/python/2.7.9/Frameworks/Python.framework/Versions/2.7/lib/python2.7/importlib/__init__.py", line 37, in import_module
    __import__(name)
  File "/Users/gaurav/GitRepo/cmpe295b/cmpe295b/urls.py", line 7, in <module>
    url(r'^linchpin/', include('linchpin.urls')),
  File "/usr/local/lib/python2.7/site-packages/django/conf/urls/__init__.py", line 28, in include
    urlconf_module = import_module(urlconf_module)
  File "/usr/local/Cellar/python/2.7.9/Frameworks/Python.framework/Versions/2.7/lib/python2.7/importlib/__init__.py", line 37, in import_module
    __import__(name)
  File "/Users/gaurav/GitRepo/cmpe295b/linchpin/urls.py", line 12, in <module>
    url(r'^adsearch/$', AdvancedSearchDirectoryView.as_view(), name='SearchDirectory')
NameError: name 'AdvancedSearchDirectoryView' is not defined
